2024-05-17 22:50:12,886 INFO    MainThread:3525 [wandb_setup.py:_flush():76] Current SDK version is 0.17.0
2024-05-17 22:50:12,890 INFO    MainThread:3525 [wandb_setup.py:_flush():76] Configure stats pid to 3525
2024-05-17 22:50:12,890 INFO    MainThread:3525 [wandb_setup.py:_flush():76] Loading settings from /root/.config/wandb/settings
2024-05-17 22:50:12,891 INFO    MainThread:3525 [wandb_setup.py:_flush():76] Loading settings from /content/drive/MyDrive/MiniGPT/wandb/settings
2024-05-17 22:50:12,891 INFO    MainThread:3525 [wandb_setup.py:_flush():76] Loading settings from environment variables: {}
2024-05-17 22:50:12,891 INFO    MainThread:3525 [wandb_setup.py:_flush():76] Applying setup settings: {'_disable_service': False}
2024-05-17 22:50:12,891 INFO    MainThread:3525 [wandb_setup.py:_flush():76] Inferring run settings from compute environment: {'program': '<python with no main file>'}
2024-05-17 22:50:12,891 INFO    MainThread:3525 [wandb_setup.py:_flush():76] Applying login settings: {}
2024-05-17 22:50:12,891 INFO    MainThread:3525 [wandb_setup.py:_flush():76] Applying login settings: {'api_key': '***REDACTED***'}
2024-05-17 22:50:12,892 INFO    MainThread:3525 [wandb_init.py:_log_setup():520] Logging user logs to /content/drive/MyDrive/MiniGPT/wandb/run-20240517_225012-wybt3r0d/logs/debug.log
2024-05-17 22:50:12,892 INFO    MainThread:3525 [wandb_init.py:_log_setup():521] Logging internal logs to /content/drive/MyDrive/MiniGPT/wandb/run-20240517_225012-wybt3r0d/logs/debug-internal.log
2024-05-17 22:50:12,892 INFO    MainThread:3525 [wandb_init.py:_jupyter_setup():466] configuring jupyter hooks <wandb.sdk.wandb_init._WandbInit object at 0x7fda53c83dc0>
2024-05-17 22:50:12,893 INFO    MainThread:3525 [wandb_init.py:init():560] calling init triggers
2024-05-17 22:50:12,893 INFO    MainThread:3525 [wandb_init.py:init():567] wandb.init called with sweep_config: {}
config: {}
2024-05-17 22:50:12,893 INFO    MainThread:3525 [wandb_init.py:init():585] re-initializing run, found existing run on stack: k13aaqxt
2024-05-17 22:50:12,895 INFO    MainThread:3525 [wandb_run.py:_finish():2103] finishing run zxzucla/dl2_proj3/k13aaqxt
2024-05-17 22:50:12,896 INFO    MainThread:3525 [wandb_run.py:_atexit_cleanup():2343] got exitcode: 0
2024-05-17 22:50:12,896 INFO    MainThread:3525 [wandb_run.py:_restore():2326] restore
2024-05-17 22:50:12,897 INFO    MainThread:3525 [wandb_run.py:_restore():2332] restore done
2024-05-17 22:51:02,605 INFO    MainThread:3525 [wandb_init.py:init():610] starting backend
2024-05-17 22:51:02,605 INFO    MainThread:3525 [wandb_init.py:init():614] setting up manager
2024-05-17 22:51:02,612 INFO    MainThread:3525 [backend.py:_multiprocessing_setup():105] multiprocessing start_methods=fork,spawn,forkserver, using: spawn
2024-05-17 22:51:02,612 INFO    MainThread:3525 [wandb_init.py:init():622] backend started and connected
2024-05-17 22:51:02,629 INFO    MainThread:3525 [wandb_run.py:_label_probe_notebook():1328] probe notebook
2024-05-17 22:51:02,933 INFO    MainThread:3525 [wandb_init.py:init():711] updated telemetry
2024-05-17 22:51:02,974 INFO    MainThread:3525 [wandb_init.py:init():744] communicating run to backend with 90.0 second timeout
2024-05-17 22:52:33,050 ERROR   MainThread:3525 [wandb_init.py:init():770] encountered error: Run initialization has timed out after 90.0 sec. 
Please refer to the documentation for additional information: https://docs.wandb.ai/guides/track/tracking-faq#initstarterror-error-communicating-with-wandb-process-
2024-05-17 22:52:33,051 ERROR   MainThread:3525 [wandb_init.py:init():1174] error in wandb.init()
Traceback (most recent call last):
  File "/usr/local/lib/python3.10/dist-packages/wandb/sdk/wandb_init.py", line 1164, in init
    return wi.init()
  File "/usr/local/lib/python3.10/dist-packages/wandb/sdk/wandb_init.py", line 776, in init
    raise error
wandb.errors.CommError: Run initialization has timed out after 90.0 sec. 
Please refer to the documentation for additional information: https://docs.wandb.ai/guides/track/tracking-faq#initstarterror-error-communicating-with-wandb-process-
2024-05-17 22:52:35,930 INFO    MainThread:3525 [wandb_settings.py:_apply_login():1895] Applying login settings: {}
2024-05-17 22:52:35,987 INFO    MainThread:3525 [wandb_setup.py:_flush():76] Current SDK version is 0.17.0
2024-05-17 22:52:35,988 INFO    MainThread:3525 [wandb_setup.py:_flush():76] Configure stats pid to 3525
2024-05-17 22:52:35,989 INFO    MainThread:3525 [wandb_setup.py:_flush():76] Loading settings from /root/.config/wandb/settings
2024-05-17 22:52:35,989 INFO    MainThread:3525 [wandb_setup.py:_flush():76] Loading settings from /content/drive/MyDrive/MiniGPT/wandb/settings
2024-05-17 22:52:35,989 INFO    MainThread:3525 [wandb_setup.py:_flush():76] Loading settings from environment variables: {}
2024-05-17 22:52:35,989 INFO    MainThread:3525 [wandb_setup.py:_flush():76] Applying setup settings: {'_disable_service': False}
2024-05-17 22:52:35,989 INFO    MainThread:3525 [wandb_setup.py:_flush():76] Inferring run settings from compute environment: {'program': '<python with no main file>'}
2024-05-17 22:52:35,989 INFO    MainThread:3525 [wandb_setup.py:_flush():76] Applying login settings: {}
2024-05-17 22:52:35,990 INFO    MainThread:3525 [wandb_setup.py:_flush():76] Applying login settings: {'api_key': '***REDACTED***'}
2024-05-17 22:52:35,990 INFO    MainThread:3525 [wandb_init.py:_log_setup():520] Logging user logs to /content/drive/MyDrive/MiniGPT/wandb/run-20240517_225235-isei18i3/logs/debug.log
2024-05-17 22:52:35,991 INFO    MainThread:3525 [wandb_init.py:_log_setup():521] Logging internal logs to /content/drive/MyDrive/MiniGPT/wandb/run-20240517_225235-isei18i3/logs/debug-internal.log
2024-05-17 22:52:35,991 INFO    MainThread:3525 [wandb_init.py:init():560] calling init triggers
2024-05-17 22:52:35,991 INFO    MainThread:3525 [wandb_init.py:init():567] wandb.init called with sweep_config: {}
config: {}
2024-05-17 22:52:35,991 INFO    MainThread:3525 [wandb_init.py:init():610] starting backend
2024-05-17 22:52:35,991 INFO    MainThread:3525 [wandb_init.py:init():614] setting up manager
2024-05-17 22:52:35,996 INFO    MainThread:3525 [backend.py:_multiprocessing_setup():105] multiprocessing start_methods=fork,spawn,forkserver, using: spawn
2024-05-17 22:52:35,997 INFO    MainThread:3525 [wandb_init.py:init():622] backend started and connected
2024-05-17 22:52:36,015 INFO    MainThread:3525 [wandb_run.py:_label_probe_notebook():1328] probe notebook
2024-05-17 22:52:36,446 INFO    MainThread:3525 [wandb_init.py:init():711] updated telemetry
2024-05-17 22:52:36,494 INFO    MainThread:3525 [wandb_init.py:init():744] communicating run to backend with 90.0 second timeout
2024-05-17 22:52:44,125 WARNING MsgRouterThr:3525 [router.py:message_loop():77] message_loop has been closed
2024-05-17 22:52:44,125 WARNING MsgRouterThr:3525 [router.py:message_loop():77] message_loop has been closed
2024-05-17 22:52:44,126 WARNING MsgRouterThr:3525 [router.py:message_loop():77] message_loop has been closed
2024-05-17 22:52:46,505 ERROR   MainThread:3525 [wandb_init.py:init():1174] error in wandb.init()
Traceback (most recent call last):
  File "/usr/local/lib/python3.10/dist-packages/wandb/sdk/wandb_init.py", line 1164, in init
    return wi.init()
  File "/usr/local/lib/python3.10/dist-packages/wandb/sdk/wandb_init.py", line 747, in init
    result = run_init_handle.wait(
  File "/usr/local/lib/python3.10/dist-packages/wandb/sdk/lib/mailbox.py", line 281, in wait
    raise MailboxError("transport failed")
wandb.sdk.lib.mailbox.MailboxError: transport failed
2024-05-17 22:53:12,313 INFO    MainThread:3525 [wandb_settings.py:_apply_login():1895] Applying login settings: {}
2024-05-17 22:53:12,367 INFO    MainThread:3525 [wandb_setup.py:_flush():76] Current SDK version is 0.17.0
2024-05-17 22:53:12,369 INFO    MainThread:3525 [wandb_setup.py:_flush():76] Configure stats pid to 3525
2024-05-17 22:53:12,369 INFO    MainThread:3525 [wandb_setup.py:_flush():76] Loading settings from /root/.config/wandb/settings
2024-05-17 22:53:12,369 INFO    MainThread:3525 [wandb_setup.py:_flush():76] Loading settings from /content/drive/MyDrive/MiniGPT/wandb/settings
2024-05-17 22:53:12,369 INFO    MainThread:3525 [wandb_setup.py:_flush():76] Loading settings from environment variables: {}
2024-05-17 22:53:12,369 INFO    MainThread:3525 [wandb_setup.py:_flush():76] Applying setup settings: {'_disable_service': False}
2024-05-17 22:53:12,370 INFO    MainThread:3525 [wandb_setup.py:_flush():76] Inferring run settings from compute environment: {'program': '<python with no main file>'}
2024-05-17 22:53:12,370 INFO    MainThread:3525 [wandb_setup.py:_flush():76] Applying login settings: {}
2024-05-17 22:53:12,370 INFO    MainThread:3525 [wandb_setup.py:_flush():76] Applying login settings: {'api_key': '***REDACTED***'}
2024-05-17 22:53:12,370 INFO    MainThread:3525 [wandb_init.py:_log_setup():520] Logging user logs to /content/drive/MyDrive/MiniGPT/wandb/run-20240517_225312-4i1o04un/logs/debug.log
2024-05-17 22:53:12,371 INFO    MainThread:3525 [wandb_init.py:_log_setup():521] Logging internal logs to /content/drive/MyDrive/MiniGPT/wandb/run-20240517_225312-4i1o04un/logs/debug-internal.log
2024-05-17 22:53:12,371 INFO    MainThread:3525 [wandb_init.py:init():560] calling init triggers
2024-05-17 22:53:12,371 INFO    MainThread:3525 [wandb_init.py:init():567] wandb.init called with sweep_config: {}
config: {}
2024-05-17 22:53:12,371 INFO    MainThread:3525 [wandb_init.py:init():610] starting backend
2024-05-17 22:53:12,372 INFO    MainThread:3525 [wandb_init.py:init():614] setting up manager
2024-05-17 22:53:12,375 ERROR   MainThread:3525 [wandb_init.py:init():1174] error in wandb.init()
Traceback (most recent call last):
  File "/usr/local/lib/python3.10/dist-packages/wandb/sdk/wandb_init.py", line 1164, in init
    return wi.init()
  File "/usr/local/lib/python3.10/dist-packages/wandb/sdk/wandb_init.py", line 615, in init
    manager._inform_init(
  File "/usr/local/lib/python3.10/dist-packages/wandb/sdk/wandb_manager.py", line 200, in _inform_init
    svc_iface._svc_inform_init(settings=settings, run_id=run_id)
  File "/usr/local/lib/python3.10/dist-packages/wandb/sdk/service/service_sock.py", line 39, in _svc_inform_init
    self._sock_client.send(inform_init=inform_init)
  File "/usr/local/lib/python3.10/dist-packages/wandb/sdk/lib/sock_client.py", line 211, in send
    self.send_server_request(server_req)
  File "/usr/local/lib/python3.10/dist-packages/wandb/sdk/lib/sock_client.py", line 155, in send_server_request
    self._send_message(msg)
  File "/usr/local/lib/python3.10/dist-packages/wandb/sdk/lib/sock_client.py", line 152, in _send_message
    self._sendall_with_error_handle(header + data)
  File "/usr/local/lib/python3.10/dist-packages/wandb/sdk/lib/sock_client.py", line 130, in _sendall_with_error_handle
    sent = self._sock.send(data)
BrokenPipeError: [Errno 32] Broken pipe
2024-05-17 22:53:16,870 INFO    MainThread:3525 [wandb_settings.py:_apply_login():1895] Applying login settings: {}
2024-05-17 22:53:16,928 INFO    MainThread:3525 [wandb_setup.py:_flush():76] Current SDK version is 0.17.0
2024-05-17 22:53:16,929 INFO    MainThread:3525 [wandb_setup.py:_flush():76] Configure stats pid to 3525
2024-05-17 22:53:16,929 INFO    MainThread:3525 [wandb_setup.py:_flush():76] Loading settings from /root/.config/wandb/settings
2024-05-17 22:53:16,930 INFO    MainThread:3525 [wandb_setup.py:_flush():76] Loading settings from /content/drive/MyDrive/MiniGPT/wandb/settings
2024-05-17 22:53:16,930 INFO    MainThread:3525 [wandb_setup.py:_flush():76] Loading settings from environment variables: {}
2024-05-17 22:53:16,930 INFO    MainThread:3525 [wandb_setup.py:_flush():76] Applying setup settings: {'_disable_service': False}
2024-05-17 22:53:16,930 INFO    MainThread:3525 [wandb_setup.py:_flush():76] Inferring run settings from compute environment: {'program': '<python with no main file>'}
2024-05-17 22:53:16,931 INFO    MainThread:3525 [wandb_setup.py:_flush():76] Applying login settings: {}
2024-05-17 22:53:16,931 INFO    MainThread:3525 [wandb_setup.py:_flush():76] Applying login settings: {'api_key': '***REDACTED***'}
2024-05-17 22:53:16,931 INFO    MainThread:3525 [wandb_init.py:_log_setup():520] Logging user logs to /content/drive/MyDrive/MiniGPT/wandb/run-20240517_225316-l8tn78ed/logs/debug.log
2024-05-17 22:53:16,932 INFO    MainThread:3525 [wandb_init.py:_log_setup():521] Logging internal logs to /content/drive/MyDrive/MiniGPT/wandb/run-20240517_225316-l8tn78ed/logs/debug-internal.log
2024-05-17 22:53:16,932 INFO    MainThread:3525 [wandb_init.py:init():560] calling init triggers
2024-05-17 22:53:16,932 INFO    MainThread:3525 [wandb_init.py:init():567] wandb.init called with sweep_config: {}
config: {}
2024-05-17 22:53:16,933 INFO    MainThread:3525 [wandb_init.py:init():610] starting backend
2024-05-17 22:53:16,933 INFO    MainThread:3525 [wandb_init.py:init():614] setting up manager
2024-05-17 22:53:16,938 ERROR   MainThread:3525 [wandb_init.py:init():1174] error in wandb.init()
Traceback (most recent call last):
  File "/usr/local/lib/python3.10/dist-packages/wandb/sdk/wandb_init.py", line 1164, in init
    return wi.init()
  File "/usr/local/lib/python3.10/dist-packages/wandb/sdk/wandb_init.py", line 615, in init
    manager._inform_init(
  File "/usr/local/lib/python3.10/dist-packages/wandb/sdk/wandb_manager.py", line 200, in _inform_init
    svc_iface._svc_inform_init(settings=settings, run_id=run_id)
  File "/usr/local/lib/python3.10/dist-packages/wandb/sdk/service/service_sock.py", line 39, in _svc_inform_init
    self._sock_client.send(inform_init=inform_init)
  File "/usr/local/lib/python3.10/dist-packages/wandb/sdk/lib/sock_client.py", line 211, in send
    self.send_server_request(server_req)
  File "/usr/local/lib/python3.10/dist-packages/wandb/sdk/lib/sock_client.py", line 155, in send_server_request
    self._send_message(msg)
  File "/usr/local/lib/python3.10/dist-packages/wandb/sdk/lib/sock_client.py", line 152, in _send_message
    self._sendall_with_error_handle(header + data)
  File "/usr/local/lib/python3.10/dist-packages/wandb/sdk/lib/sock_client.py", line 130, in _sendall_with_error_handle
    sent = self._sock.send(data)
BrokenPipeError: [Errno 32] Broken pipe
2024-05-17 22:53:32,365 INFO    MainThread:3525 [wandb_settings.py:_apply_login():1895] Applying login settings: {}
2024-05-17 22:53:32,413 INFO    MainThread:3525 [wandb_setup.py:_flush():76] Current SDK version is 0.17.0
2024-05-17 22:53:32,414 INFO    MainThread:3525 [wandb_setup.py:_flush():76] Configure stats pid to 3525
2024-05-17 22:53:32,415 INFO    MainThread:3525 [wandb_setup.py:_flush():76] Loading settings from /root/.config/wandb/settings
2024-05-17 22:53:32,416 INFO    MainThread:3525 [wandb_setup.py:_flush():76] Loading settings from /content/drive/MyDrive/MiniGPT/wandb/settings
2024-05-17 22:53:32,416 INFO    MainThread:3525 [wandb_setup.py:_flush():76] Loading settings from environment variables: {}
2024-05-17 22:53:32,417 INFO    MainThread:3525 [wandb_setup.py:_flush():76] Applying setup settings: {'_disable_service': False}
2024-05-17 22:53:32,417 INFO    MainThread:3525 [wandb_setup.py:_flush():76] Inferring run settings from compute environment: {'program': '<python with no main file>'}
2024-05-17 22:53:32,417 INFO    MainThread:3525 [wandb_setup.py:_flush():76] Applying login settings: {}
2024-05-17 22:53:32,418 INFO    MainThread:3525 [wandb_setup.py:_flush():76] Applying login settings: {'api_key': '***REDACTED***'}
2024-05-17 22:53:32,418 INFO    MainThread:3525 [wandb_init.py:_log_setup():520] Logging user logs to /content/drive/MyDrive/MiniGPT/wandb/run-20240517_225332-0kjp1fac/logs/debug.log
2024-05-17 22:53:32,419 INFO    MainThread:3525 [wandb_init.py:_log_setup():521] Logging internal logs to /content/drive/MyDrive/MiniGPT/wandb/run-20240517_225332-0kjp1fac/logs/debug-internal.log
2024-05-17 22:53:32,419 INFO    MainThread:3525 [wandb_init.py:init():560] calling init triggers
2024-05-17 22:53:32,419 INFO    MainThread:3525 [wandb_init.py:init():567] wandb.init called with sweep_config: {}
config: {}
2024-05-17 22:53:32,420 INFO    MainThread:3525 [wandb_init.py:init():610] starting backend
2024-05-17 22:53:32,420 INFO    MainThread:3525 [wandb_init.py:init():614] setting up manager
2024-05-17 22:53:32,424 ERROR   MainThread:3525 [wandb_init.py:init():1174] error in wandb.init()
Traceback (most recent call last):
  File "/usr/local/lib/python3.10/dist-packages/wandb/sdk/wandb_init.py", line 1164, in init
    return wi.init()
  File "/usr/local/lib/python3.10/dist-packages/wandb/sdk/wandb_init.py", line 615, in init
    manager._inform_init(
  File "/usr/local/lib/python3.10/dist-packages/wandb/sdk/wandb_manager.py", line 200, in _inform_init
    svc_iface._svc_inform_init(settings=settings, run_id=run_id)
  File "/usr/local/lib/python3.10/dist-packages/wandb/sdk/service/service_sock.py", line 39, in _svc_inform_init
    self._sock_client.send(inform_init=inform_init)
  File "/usr/local/lib/python3.10/dist-packages/wandb/sdk/lib/sock_client.py", line 211, in send
    self.send_server_request(server_req)
  File "/usr/local/lib/python3.10/dist-packages/wandb/sdk/lib/sock_client.py", line 155, in send_server_request
    self._send_message(msg)
  File "/usr/local/lib/python3.10/dist-packages/wandb/sdk/lib/sock_client.py", line 152, in _send_message
    self._sendall_with_error_handle(header + data)
  File "/usr/local/lib/python3.10/dist-packages/wandb/sdk/lib/sock_client.py", line 130, in _sendall_with_error_handle
    sent = self._sock.send(data)
BrokenPipeError: [Errno 32] Broken pipe
2024-05-17 22:56:45,445 INFO    MainThread:3525 [wandb_settings.py:_apply_login():1895] Applying login settings: {}
2024-05-17 22:56:45,496 INFO    MainThread:3525 [wandb_setup.py:_flush():76] Current SDK version is 0.17.0
2024-05-17 22:56:45,498 INFO    MainThread:3525 [wandb_setup.py:_flush():76] Configure stats pid to 3525
2024-05-17 22:56:45,499 INFO    MainThread:3525 [wandb_setup.py:_flush():76] Loading settings from /root/.config/wandb/settings
2024-05-17 22:56:45,500 INFO    MainThread:3525 [wandb_setup.py:_flush():76] Loading settings from /content/drive/MyDrive/MiniGPT/wandb/settings
2024-05-17 22:56:45,500 INFO    MainThread:3525 [wandb_setup.py:_flush():76] Loading settings from environment variables: {}
2024-05-17 22:56:45,501 INFO    MainThread:3525 [wandb_setup.py:_flush():76] Applying setup settings: {'_disable_service': False}
2024-05-17 22:56:45,502 INFO    MainThread:3525 [wandb_setup.py:_flush():76] Inferring run settings from compute environment: {'program': '<python with no main file>'}
2024-05-17 22:56:45,502 INFO    MainThread:3525 [wandb_setup.py:_flush():76] Applying login settings: {}
2024-05-17 22:56:45,503 INFO    MainThread:3525 [wandb_setup.py:_flush():76] Applying login settings: {'api_key': '***REDACTED***'}
2024-05-17 22:56:45,504 INFO    MainThread:3525 [wandb_init.py:_log_setup():520] Logging user logs to /content/drive/MyDrive/MiniGPT/wandb/run-20240517_225645-yvue8hlo/logs/debug.log
2024-05-17 22:56:45,505 INFO    MainThread:3525 [wandb_init.py:_log_setup():521] Logging internal logs to /content/drive/MyDrive/MiniGPT/wandb/run-20240517_225645-yvue8hlo/logs/debug-internal.log
2024-05-17 22:56:45,506 INFO    MainThread:3525 [wandb_init.py:init():560] calling init triggers
2024-05-17 22:56:45,506 INFO    MainThread:3525 [wandb_init.py:init():567] wandb.init called with sweep_config: {}
config: {}
2024-05-17 22:56:45,507 INFO    MainThread:3525 [wandb_init.py:init():610] starting backend
2024-05-17 22:56:45,508 INFO    MainThread:3525 [wandb_init.py:init():614] setting up manager
2024-05-17 22:56:45,514 ERROR   MainThread:3525 [wandb_init.py:init():1174] error in wandb.init()
Traceback (most recent call last):
  File "/usr/local/lib/python3.10/dist-packages/wandb/sdk/wandb_init.py", line 1164, in init
    return wi.init()
  File "/usr/local/lib/python3.10/dist-packages/wandb/sdk/wandb_init.py", line 615, in init
    manager._inform_init(
  File "/usr/local/lib/python3.10/dist-packages/wandb/sdk/wandb_manager.py", line 200, in _inform_init
    svc_iface._svc_inform_init(settings=settings, run_id=run_id)
  File "/usr/local/lib/python3.10/dist-packages/wandb/sdk/service/service_sock.py", line 39, in _svc_inform_init
    self._sock_client.send(inform_init=inform_init)
  File "/usr/local/lib/python3.10/dist-packages/wandb/sdk/lib/sock_client.py", line 211, in send
    self.send_server_request(server_req)
  File "/usr/local/lib/python3.10/dist-packages/wandb/sdk/lib/sock_client.py", line 155, in send_server_request
    self._send_message(msg)
  File "/usr/local/lib/python3.10/dist-packages/wandb/sdk/lib/sock_client.py", line 152, in _send_message
    self._sendall_with_error_handle(header + data)
  File "/usr/local/lib/python3.10/dist-packages/wandb/sdk/lib/sock_client.py", line 130, in _sendall_with_error_handle
    sent = self._sock.send(data)
BrokenPipeError: [Errno 32] Broken pipe
2024-05-17 22:56:58,812 INFO    MainThread:3525 [wandb_settings.py:_apply_login():1895] Applying login settings: {}
2024-05-17 22:56:58,871 INFO    MainThread:3525 [wandb_setup.py:_flush():76] Current SDK version is 0.17.0
2024-05-17 22:56:58,873 INFO    MainThread:3525 [wandb_setup.py:_flush():76] Configure stats pid to 3525
2024-05-17 22:56:58,873 INFO    MainThread:3525 [wandb_setup.py:_flush():76] Loading settings from /root/.config/wandb/settings
2024-05-17 22:56:58,874 INFO    MainThread:3525 [wandb_setup.py:_flush():76] Loading settings from /content/drive/MyDrive/MiniGPT/wandb/settings
2024-05-17 22:56:58,874 INFO    MainThread:3525 [wandb_setup.py:_flush():76] Loading settings from environment variables: {}
2024-05-17 22:56:58,875 INFO    MainThread:3525 [wandb_setup.py:_flush():76] Applying setup settings: {'_disable_service': False}
2024-05-17 22:56:58,876 INFO    MainThread:3525 [wandb_setup.py:_flush():76] Inferring run settings from compute environment: {'program': '<python with no main file>'}
2024-05-17 22:56:58,876 INFO    MainThread:3525 [wandb_setup.py:_flush():76] Applying login settings: {}
2024-05-17 22:56:58,877 INFO    MainThread:3525 [wandb_setup.py:_flush():76] Applying login settings: {'api_key': '***REDACTED***'}
2024-05-17 22:56:58,878 INFO    MainThread:3525 [wandb_init.py:_log_setup():520] Logging user logs to /content/drive/MyDrive/MiniGPT/wandb/run-20240517_225658-274iw3nv/logs/debug.log
2024-05-17 22:56:58,878 INFO    MainThread:3525 [wandb_init.py:_log_setup():521] Logging internal logs to /content/drive/MyDrive/MiniGPT/wandb/run-20240517_225658-274iw3nv/logs/debug-internal.log
2024-05-17 22:56:58,879 INFO    MainThread:3525 [wandb_init.py:init():560] calling init triggers
2024-05-17 22:56:58,881 INFO    MainThread:3525 [wandb_init.py:init():567] wandb.init called with sweep_config: {}
config: {}
2024-05-17 22:56:58,882 INFO    MainThread:3525 [wandb_init.py:init():610] starting backend
2024-05-17 22:56:58,882 INFO    MainThread:3525 [wandb_init.py:init():614] setting up manager
2024-05-17 22:56:58,887 ERROR   MainThread:3525 [wandb_init.py:init():1174] error in wandb.init()
Traceback (most recent call last):
  File "/usr/local/lib/python3.10/dist-packages/wandb/sdk/wandb_init.py", line 1164, in init
    return wi.init()
  File "/usr/local/lib/python3.10/dist-packages/wandb/sdk/wandb_init.py", line 615, in init
    manager._inform_init(
  File "/usr/local/lib/python3.10/dist-packages/wandb/sdk/wandb_manager.py", line 200, in _inform_init
    svc_iface._svc_inform_init(settings=settings, run_id=run_id)
  File "/usr/local/lib/python3.10/dist-packages/wandb/sdk/service/service_sock.py", line 39, in _svc_inform_init
    self._sock_client.send(inform_init=inform_init)
  File "/usr/local/lib/python3.10/dist-packages/wandb/sdk/lib/sock_client.py", line 211, in send
    self.send_server_request(server_req)
  File "/usr/local/lib/python3.10/dist-packages/wandb/sdk/lib/sock_client.py", line 155, in send_server_request
    self._send_message(msg)
  File "/usr/local/lib/python3.10/dist-packages/wandb/sdk/lib/sock_client.py", line 152, in _send_message
    self._sendall_with_error_handle(header + data)
  File "/usr/local/lib/python3.10/dist-packages/wandb/sdk/lib/sock_client.py", line 130, in _sendall_with_error_handle
    sent = self._sock.send(data)
BrokenPipeError: [Errno 32] Broken pipe
